<?xml version="1.0" encoding="UTF-8"?>
<!-- Generated by org.testng.reporters.JUnitReportReporter -->
<testsuite hostname="yuzgdeMacBook-Pro.local" failures="0" tests="3" name="com.yiibai9.TestApi" time="0.304" errors="1" timestamp="7 Dec 2020 06:57:00 GMT">
  <testcase classname="com.yiibai9.TestApi" name="test3Fail" time="0.076">
    <error message="expected [null] but found [{&quot;procode&quot;:&quot;1222&quot;,
    &quot;word&quot;:&quot;hello&quot;,
&quot;dubbodata&quot;:&quot;132078224594309120&quot;,
&quot;dict&quot;:&quot;{\&quot;key1\&quot;:\&quot;value1\&quot;}&quot;,
&quot;json&quot;:{&quot;key1&quot;:&quot;value1&quot;,&quot;key2&quot;:&quot;value2&quot;},
&quot;dict2&quot;:&quot;{\&quot;result\&quot;:[{\&quot;name\&quot;:1},{\&quot;name\&quot;:2}]}&quot;,
&quot;emptyKey&quot;:&quot;&quot;,
&quot;emptyList&quot;:[],
  &quot;data&quot;:[{&quot;name&quot;:1},

{&quot;name&quot;:2}]}]" type="java.lang.AssertionError">
      <![CDATA[java.lang.AssertionError: expected [null] but found [{"procode":"1222",
    "word":"hello",
"dubbodata":"132078224594309120",
"dict":"{\"key1\":\"value1\"}",
"json":{"key1":"value1","key2":"value2"},
"dict2":"{\"result\":[{\"name\":1},{\"name\":2}]}",
"emptyKey":"",
"emptyList":[],
  "data":[{"name":1},

{"name":2}]}]
	at org.testng.Assert.fail(Assert.java:94)
	at org.testng.Assert.failNotSame(Assert.java:490)
	at org.testng.Assert.assertNull(Assert.java:426)
	at org.testng.Assert.assertNull(Assert.java:415)
	at com.yiibai9.TestApi.test3Fail(TestApi.java:72)
	at java.base/jdk.internal.reflect.NativeMethodAccessorImpl.invoke0(Native Method)
	at java.base/jdk.internal.reflect.NativeMethodAccessorImpl.invoke(NativeMethodAccessorImpl.java:62)
	at java.base/jdk.internal.reflect.DelegatingMethodAccessorImpl.invoke(DelegatingMethodAccessorImpl.java:43)
	at java.base/java.lang.reflect.Method.invoke(Method.java:564)
	at org.testng.internal.MethodInvocationHelper.invokeMethod(MethodInvocationHelper.java:84)
	at org.testng.internal.Invoker.invokeMethod(Invoker.java:714)
	at org.testng.internal.Invoker.invokeTestMethod(Invoker.java:901)
	at org.testng.internal.Invoker.invokeTestMethods(Invoker.java:1231)
	at org.testng.internal.TestMethodWorker.invokeTestMethods(TestMethodWorker.java:127)
	at org.testng.internal.TestMethodWorker.run(TestMethodWorker.java:111)
	at org.testng.TestRunner.privateRun(TestRunner.java:767)
	at org.testng.TestRunner.run(TestRunner.java:617)
	at org.testng.SuiteRunner.runTest(SuiteRunner.java:334)
	at org.testng.SuiteRunner.runSequentially(SuiteRunner.java:329)
	at org.testng.SuiteRunner.privateRun(SuiteRunner.java:291)
	at org.testng.SuiteRunner.run(SuiteRunner.java:240)
	at org.testng.SuiteRunnerWorker.runSuite(SuiteRunnerWorker.java:52)
	at org.testng.SuiteRunnerWorker.run(SuiteRunnerWorker.java:86)
	at org.testng.TestNG.runSuitesSequentially(TestNG.java:1224)
	at org.testng.TestNG.runSuitesLocally(TestNG.java:1149)
	at org.testng.TestNG.run(TestNG.java:1057)
	at org.testng.remote.AbstractRemoteTestNG.run(AbstractRemoteTestNG.java:132)
	at org.testng.remote.RemoteTestNG.initAndRun(RemoteTestNG.java:236)
	at org.testng.remote.RemoteTestNG.main(RemoteTestNG.java:81)
]]>
    </error>
  </testcase> <!-- test3Fail -->
  <testcase classname="com.yiibai9.TestApi" name="test1Post" time="0.155"/>
  <testcase classname="com.yiibai9.TestApi" name="test2Get" time="0.073"/>
</testsuite> <!-- com.yiibai9.TestApi -->
